Workbook

Sheet Programa
A1: Nivel | B1: CURSO-Agenda | C1: NRC | D1: Semestre | E1: CodMaestroOferta | F1: Nombre Curso Oferta | G1: Nombre Curso | H1: CodMaestro | I1: NombreCursoOferta | J1: CodCursoOferta | K1: IdPlantilla | L1: IdSemestre | M1: IDCURSO | N1: URL
A2: =_xlfn.XLOOKUP(Tabla1[[#This Row],[CodMaestro]],UnidadesOrganizaciones!D:D,UnidadesOrganizaciones!L:L,"***") -> CVFA | B2: Gestión de tiempos, riesgos y costos A | C2: 63604 | D2: 202341 | E2: =_xlfn.TEXTBEFORE(H2,"MaestroP") -> #N/A | F2: =_xlfn.XLOOKUP(Tabla1[[#This Row],[CodMaestro]],UnidadesOrganizaciones!D:D,UnidadesOrganizaciones!C:C,"***") -> GESTIÓN DE TIEMPOS, RIESGOS Y COSTOS -MaestroC | G2: =LEFT(F2,FIND(" -",F2&" -")-1) -> GESTIÓN DE TIEMPOS, RIESGOS Y COSTOS | H2: CEOE-0320-MaestroC | I2: =Tabla1[[#This Row],[Nombre Curso]]&" - "&Tabla1[[#This Row],[Semestre]]&"-"&Tabla1[[#This Row],[NRC]] -> GESTIÓN DE TIEMPOS, RIESGOS Y COSTOS - 202341-63604 | J2: =E2&D2&"-"&C2 -> #N/A | K2: =_xlfn.XLOOKUP(Tabla1[[#This Row],[CodMaestro]],UnidadesOrganizaciones!D:D,UnidadesOrganizaciones!Q:Q,"***") -> 6691 | L2: =_xlfn.XLOOKUP(TEXT(Tabla1[[#This Row],[Semestre]],"######"),'CursosBS'!E:E,'CursosBS'!A:A,"***") -> 40978 | M2: =_xlfn.XLOOKUP(Tabla1[[#This Row],[CodCursoOferta]],'CursosBS'!E:E,'CursosBS'!A:A,"*NoExiste*") -> #N/A | N2: ="https://virtual.upb.edu.co/d2l/home/"&Tabla1[[#This Row],[IDCURSO]] -> #N/A
A3: =_xlfn.XLOOKUP(Tabla1[[#This Row],[CodMaestro]],UnidadesOrganizaciones!D:D,UnidadesOrganizaciones!L:L,"***") -> CVFC | B3: Emprendimiento Nivel Básico | C3: 51277 | D3: 202650 | E3: =_xlfn.TEXTBEFORE(H3,"MaestroP") -> ADEM-3173- | F3: =_xlfn.XLOOKUP(Tabla1[[#This Row],[CodMaestro]],UnidadesOrganizaciones!D:D,UnidadesOrganizaciones!C:C,"***") -> Emprendimiento Nivel Básico -QMMaestroP(R) | G3: =LEFT(F3,FIND(" -",F3&" -")-1) -> Emprendimiento Nivel Básico | H3: ADEM-3173-MaestroP | I3: =Tabla1[[#This Row],[Nombre Curso]]&" - "&Tabla1[[#This Row],[Semestre]]&"-"&Tabla1[[#This Row],[NRC]] -> Emprendimiento Nivel Básico - 202650-51277 | J3: =E3&D3&"-"&C3 -> ADEM-3173-202650-51277 | K3: =_xlfn.XLOOKUP(Tabla1[[#This Row],[CodMaestro]],UnidadesOrganizaciones!D:D,UnidadesOrganizaciones!Q:Q,"***") -> 38966 | L3: =_xlfn.XLOOKUP(TEXT(Tabla1[[#This Row],[Semestre]],"######"),'CursosBS'!E:E,'CursosBS'!A:A,"***") -> 77362 | M3: =_xlfn.XLOOKUP(Tabla1[[#This Row],[CodCursoOferta]],'CursosBS'!E:E,'CursosBS'!A:A,"*NoExiste*") -> *NoExiste* | N3: ="https://virtual.upb.edu.co/d2l/home/"&Tabla1[[#This Row],[IDCURSO]] -> https://virtual.upb.edu.co/d2l/home/*NoExiste*
A4: =_xlfn.XLOOKUP(Tabla1[[#This Row],[CodMaestro]],UnidadesOrganizaciones!D:D,UnidadesOrganizaciones!L:L,"***") -> CVFC | B4: Emprendimiento Nivel Básico | C4: 51278 | D4: 202650 | E4: =_xlfn.TEXTBEFORE(H4,"MaestroP") -> ADEM-3173- | F4: =_xlfn.XLOOKUP(Tabla1[[#This Row],[CodMaestro]],UnidadesOrganizaciones!D:D,UnidadesOrganizaciones!C:C,"***") -> Emprendimiento Nivel Básico -QMMaestroP(R) | G4: =LEFT(F4,FIND(" -",F4&" -")-1) -> Emprendimiento Nivel Básico | H4: ADEM-3173-MaestroP | I4: =Tabla1[[#This Row],[Nombre Curso]]&" - "&Tabla1[[#This Row],[Semestre]]&"-"&Tabla1[[#This Row],[NRC]] -> Emprendimiento Nivel Básico - 202650-51278 | J4: =E4&D4&"-"&C4 -> ADEM-3173-202650-51278 | K4: =_xlfn.XLOOKUP(Tabla1[[#This Row],[CodMaestro]],UnidadesOrganizaciones!D:D,UnidadesOrganizaciones!Q:Q,"***") -> 38966 | L4: =_xlfn.XLOOKUP(TEXT(Tabla1[[#This Row],[Semestre]],"######"),'CursosBS'!E:E,'CursosBS'!A:A,"***") -> 77362 | M4: =_xlfn.XLOOKUP(Tabla1[[#This Row],[CodCursoOferta]],'CursosBS'!E:E,'CursosBS'!A:A,"*NoExiste*") -> *NoExiste* | N4: ="https://virtual.upb.edu.co/d2l/home/"&Tabla1[[#This Row],[IDCURSO]] -> https://virtual.upb.edu.co/d2l/home/*NoExiste*
A5: =_xlfn.XLOOKUP(Tabla1[[#This Row],[CodMaestro]],UnidadesOrganizaciones!D:D,UnidadesOrganizaciones!L:L,"***") -> CVFC | B5: Emprendimiento Nivel Básico | C5: 51279 | D5: 202650 | E5: =_xlfn.TEXTBEFORE(H5,"MaestroP") -> ADEM-3173- | F5: =_xlfn.XLOOKUP(Tabla1[[#This Row],[CodMaestro]],UnidadesOrganizaciones!D:D,UnidadesOrganizaciones!C:C,"***") -> Emprendimiento Nivel Básico -QMMaestroP(R) | G5: =LEFT(F5,FIND(" -",F5&" -")-1) -> Emprendimiento Nivel Básico | H5: ADEM-3173-MaestroP | I5: =Tabla1[[#This Row],[Nombre Curso]]&" - "&Tabla1[[#This Row],[Semestre]]&"-"&Tabla1[[#This Row],[NRC]] -> Emprendimiento Nivel Básico - 202650-51279 | J5: =E5&D5&"-"&C5 -> ADEM-3173-202650-51279 | K5: =_xlfn.XLOOKUP(Tabla1[[#This Row],[CodMaestro]],UnidadesOrganizaciones!D:D,UnidadesOrganizaciones!Q:Q,"***") -> 38966 | L5: =_xlfn.XLOOKUP(TEXT(Tabla1[[#This Row],[Semestre]],"######"),'CursosBS'!E:E,'CursosBS'!A:A,"***") -> 77362 | M5: =_xlfn.XLOOKUP(Tabla1[[#This Row],[CodCursoOferta]],'CursosBS'!E:E,'CursosBS'!A:A,"*NoExiste*") -> *NoExiste* | N5: ="https://virtual.upb.edu.co/d2l/home/"&Tabla1[[#This Row],[IDCURSO]] -> https://virtual.upb.edu.co/d2l/home/*NoExiste*
A6: =_xlfn.XLOOKUP(Tabla1[[#This Row],[CodMaestro]],UnidadesOrganizaciones!D:D,UnidadesOrganizaciones!L:L,"***") -> CVFC | B6: Emprendimiento Nivel Básico | C6: 51280 | D6: 202650 | E6: =_xlfn.TEXTBEFORE(H6,"MaestroP") -> ADEM-3173- | F6: =_xlfn.XLOOKUP(Tabla1[[#This Row],[CodMaestro]],UnidadesOrganizaciones!D:D,UnidadesOrganizaciones!C:C,"***") -> Emprendimiento Nivel Básico -QMMaestroP(R) | G6: =LEFT(F6,FIND(" -",F6&" -")-1) -> Emprendimiento Nivel Básico | H6: ADEM-3173-MaestroP | I6: =Tabla1[[#This Row],[Nombre Curso]]&" - "&Tabla1[[#This Row],[Semestre]]&"-"&Tabla1[[#This Row],[NRC]] -> Emprendimiento Nivel Básico - 202650-51280 | J6: =E6&D6&"-"&C6 -> ADEM-3173-202650-51280 | K6: =_xlfn.XLOOKUP(Tabla1[[#This Row],[CodMaestro]],UnidadesOrganizaciones!D:D,UnidadesOrganizaciones!Q:Q,"***") -> 38966 | L6: =_xlfn.XLOOKUP(TEXT(Tabla1[[#This Row],[Semestre]],"######"),'CursosBS'!E:E,'CursosBS'!A:A,"***") -> 77362 | M6: =_xlfn.XLOOKUP(Tabla1[[#This Row],[CodCursoOferta]],'CursosBS'!E:E,'CursosBS'!A:A,"*NoExiste*") -> *NoExiste* | N6: ="https://virtual.upb.edu.co/d2l/home/"&Tabla1[[#This Row],[IDCURSO]] -> https://virtual.upb.edu.co/d2l/home/*NoExiste*
A7: =_xlfn.XLOOKUP(Tabla1[[#This Row],[CodMaestro]],UnidadesOrganizaciones!D:D,UnidadesOrganizaciones!L:L,"***") -> CVFC | B7: Emprendimiento Nivel Básico | C7: 51281 | D7: 202650 | E7: =_xlfn.TEXTBEFORE(H7,"MaestroP") -> ADEM-3173- | F7: =_xlfn.XLOOKUP(Tabla1[[#This Row],[CodMaestro]],UnidadesOrganizaciones!D:D,UnidadesOrganizaciones!C:C,"***") -> Emprendimiento Nivel Básico -QMMaestroP(R) | G7: =LEFT(F7,FIND(" -",F7&" -")-1) -> Emprendimiento Nivel Básico | H7: ADEM-3173-MaestroP | I7: =Tabla1[[#This Row],[Nombre Curso]]&" - "&Tabla1[[#This Row],[Semestre]]&"-"&Tabla1[[#This Row],[NRC]] -> Emprendimiento Nivel Básico - 202650-51281 | J7: =E7&D7&"-"&C7 -> ADEM-3173-202650-51281 | K7: =_xlfn.XLOOKUP(Tabla1[[#This Row],[CodMaestro]],UnidadesOrganizaciones!D:D,UnidadesOrganizaciones!Q:Q,"***") -> 38966 | L7: =_xlfn.XLOOKUP(TEXT(Tabla1[[#This Row],[Semestre]],"######"),'CursosBS'!E:E,'CursosBS'!A:A,"***") -> 77362 | M7: =_xlfn.XLOOKUP(Tabla1[[#This Row],[CodCursoOferta]],'CursosBS'!E:E,'CursosBS'!A:A,"*NoExiste*") -> *NoExiste* | N7: ="https://virtual.upb.edu.co/d2l/home/"&Tabla1[[#This Row],[IDCURSO]] -> https://virtual.upb.edu.co/d2l/home/*NoExiste*
A8: =_xlfn.XLOOKUP(Tabla1[[#This Row],[CodMaestro]],UnidadesOrganizaciones!D:D,UnidadesOrganizaciones!L:L,"***") -> CVFC | B8: Emprendimiento Nivel Básico | C8: 51282 | D8: 202650 | E8: =_xlfn.TEXTBEFORE(H8,"MaestroP") -> ADEM-3173- | F8: =_xlfn.XLOOKUP(Tabla1[[#This Row],[CodMaestro]],UnidadesOrganizaciones!D:D,UnidadesOrganizaciones!C:C,"***") -> Emprendimiento Nivel Básico -QMMaestroP(R) | G8: =LEFT(F8,FIND(" -",F8&" -")-1) -> Emprendimiento Nivel Básico | H8: ADEM-3173-MaestroP | I8: =Tabla1[[#This Row],[Nombre Curso]]&" - "&Tabla1[[#This Row],[Semestre]]&"-"&Tabla1[[#This Row],[NRC]] -> Emprendimiento Nivel Básico - 202650-51282 | J8: =E8&D8&"-"&C8 -> ADEM-3173-202650-51282 | K8: =_xlfn.XLOOKUP(Tabla1[[#This Row],[CodMaestro]],UnidadesOrganizaciones!D:D,UnidadesOrganizaciones!Q:Q,"***") -> 38966 | L8: =_xlfn.XLOOKUP(TEXT(Tabla1[[#This Row],[Semestre]],"######"),'CursosBS'!E:E,'CursosBS'!A:A,"***") -> 77362 | M8: =_xlfn.XLOOKUP(Tabla1[[#This Row],[CodCursoOferta]],'CursosBS'!E:E,'CursosBS'!A:A,"*NoExiste*") -> *NoExiste* | N8: ="https://virtual.upb.edu.co/d2l/home/"&Tabla1[[#This Row],[IDCURSO]] -> https://virtual.upb.edu.co/d2l/home/*NoExiste*
A9: =_xlfn.XLOOKUP(Tabla1[[#This Row],[CodMaestro]],UnidadesOrganizaciones!D:D,UnidadesOrganizaciones!L:L,"***") -> CVFC | B9: Emprendimiento Nivel Básico | C9: 51283 | D9: 202650 | E9: =_xlfn.TEXTBEFORE(H9,"MaestroP") -> ADEM-3173- | F9: =_xlfn.XLOOKUP(Tabla1[[#This Row],[CodMaestro]],UnidadesOrganizaciones!D:D,UnidadesOrganizaciones!C:C,"***") -> Emprendimiento Nivel Básico -QMMaestroP(R) | G9: =LEFT(F9,FIND(" -",F9&" -")-1) -> Emprendimiento Nivel Básico | H9: ADEM-3173-MaestroP | I9: =Tabla1[[#This Row],[Nombre Curso]]&" - "&Tabla1[[#This Row],[Semestre]]&"-"&Tabla1[[#This Row],[NRC]] -> Emprendimiento Nivel Básico - 202650-51283 | J9: =E9&D9&"-"&C9 -> ADEM-3173-202650-51283 | K9: =_xlfn.XLOOKUP(Tabla1[[#This Row],[CodMaestro]],UnidadesOrganizaciones!D:D,UnidadesOrganizaciones!Q:Q,"***") -> 38966 | L9: =_xlfn.XLOOKUP(TEXT(Tabla1[[#This Row],[Semestre]],"######"),'CursosBS'!E:E,'CursosBS'!A:A,"***") -> 77362 | M9: =_xlfn.XLOOKUP(Tabla1[[#This Row],[CodCursoOferta]],'CursosBS'!E:E,'CursosBS'!A:A,"*NoExiste*") -> *NoExiste* | N9: ="https://virtual.upb.edu.co/d2l/home/"&Tabla1[[#This Row],[IDCURSO]] -> https://virtual.upb.edu.co/d2l/home/*NoExiste*
A10: =_xlfn.XLOOKUP(Tabla1[[#This Row],[CodMaestro]],UnidadesOrganizaciones!D:D,UnidadesOrganizaciones!L:L,"***") -> CVFC | B10: Emprendimiento Nivel Básico | C10: 51284 | D10: 202650 | E10: =_xlfn.TEXTBEFORE(H10,"MaestroP") -> ADEM-3173- | F10: =_xlfn.XLOOKUP(Tabla1[[#This Row],[CodMaestro]],UnidadesOrganizaciones!D:D,UnidadesOrganizaciones!C:C,"***") -> Emprendimiento Nivel Básico -QMMaestroP(R) | G10: =LEFT(F10,FIND(" -",F10&" -")-1) -> Emprendimiento Nivel Básico | H10: ADEM-3173-MaestroP | I10: =Tabla1[[#This Row],[Nombre Curso]]&" - "&Tabla1[[#This Row],[Semestre]]&"-"&Tabla1[[#This Row],[NRC]] -> Emprendimiento Nivel Básico - 202650-51284 | J10: =E10&D10&"-"&C10 -> ADEM-3173-202650-51284 | K10: =_xlfn.XLOOKUP(Tabla1[[#This Row],[CodMaestro]],UnidadesOrganizaciones!D:D,UnidadesOrganizaciones!Q:Q,"***") -> 38966 | L10: =_xlfn.XLOOKUP(TEXT(Tabla1[[#This Row],[Semestre]],"######"),'CursosBS'!E:E,'CursosBS'!A:A,"***") -> 77362 | M10: =_xlfn.XLOOKUP(Tabla1[[#This Row],[CodCursoOferta]],'CursosBS'!E:E,'CursosBS'!A:A,"*NoExiste*") -> *NoExiste* | N10: ="https://virtual.upb.edu.co/d2l/home/"&Tabla1[[#This Row],[IDCURSO]] -> https://virtual.upb.edu.co/d2l/home/*NoExiste*
A11: =_xlfn.XLOOKUP(Tabla1[[#This Row],[CodMaestro]],UnidadesOrganizaciones!D:D,UnidadesOrganizaciones!L:L,"***") -> CVFC | B11: Emprendimiento Nivel Básico | C11: 51285 | D11: 202650 | E11: =_xlfn.TEXTBEFORE(H11,"MaestroP") -> ADEM-3173- | F11: =_xlfn.XLOOKUP(Tabla1[[#This Row],[CodMaestro]],UnidadesOrganizaciones!D:D,UnidadesOrganizaciones!C:C,"***") -> Emprendimiento Nivel Básico -QMMaestroP(R) | G11: =LEFT(F11,FIND(" -",F11&" -")-1) -> Emprendimiento Nivel Básico | H11: ADEM-3173-MaestroP | I11: =Tabla1[[#This Row],[Nombre Curso]]&" - "&Tabla1[[#This Row],[Semestre]]&"-"&Tabla1[[#This Row],[NRC]] -> Emprendimiento Nivel Básico - 202650-51285 | J11: =E11&D11&"-"&C11 -> ADEM-3173-202650-51285 | K11: =_xlfn.XLOOKUP(Tabla1[[#This Row],[CodMaestro]],UnidadesOrganizaciones!D:D,UnidadesOrganizaciones!Q:Q,"***") -> 38966 | L11: =_xlfn.XLOOKUP(TEXT(Tabla1[[#This Row],[Semestre]],"######"),'CursosBS'!E:E,'CursosBS'!A:A,"***") -> 77362 | M11: =_xlfn.XLOOKUP(Tabla1[[#This Row],[CodCursoOferta]],'CursosBS'!E:E,'CursosBS'!A:A,"*NoExiste*") -> *NoExiste* | N11: ="https://virtual.upb.edu.co/d2l/home/"&Tabla1[[#This Row],[IDCURSO]] -> https://virtual.upb.edu.co/d2l/home/*NoExiste*
A12: =_xlfn.XLOOKUP(Tabla1[[#This Row],[CodMaestro]],UnidadesOrganizaciones!D:D,UnidadesOrganizaciones!L:L,"***") -> CVFC | B12: Emprendimiento Nivel Básico | C12: 51286 | D12: 202650 | E12: =_xlfn.TEXTBEFORE(H12,"MaestroP") -> ADEM-3173- | F12: =_xlfn.XLOOKUP(Tabla1[[#This Row],[CodMaestro]],UnidadesOrganizaciones!D:D,UnidadesOrganizaciones!C:C,"***") -> Emprendimiento Nivel Básico -QMMaestroP(R) | G12: =LEFT(F12,FIND(" -",F12&" -")-1) -> Emprendimiento Nivel Básico | H12: ADEM-3173-MaestroP | I12: =Tabla1[[#This Row],[Nombre Curso]]&" - "&Tabla1[[#This Row],[Semestre]]&"-"&Tabla1[[#This Row],[NRC]] -> Emprendimiento Nivel Básico - 202650-51286 | J12: =E12&D12&"-"&C12 -> ADEM-3173-202650-51286 | K12: =_xlfn.XLOOKUP(Tabla1[[#This Row],[CodMaestro]],UnidadesOrganizaciones!D:D,UnidadesOrganizaciones!Q:Q,"***") -> 38966 | L12: =_xlfn.XLOOKUP(TEXT(Tabla1[[#This Row],[Semestre]],"######"),'CursosBS'!E:E,'CursosBS'!A:A,"***") -> 77362 | M12: =_xlfn.XLOOKUP(Tabla1[[#This Row],[CodCursoOferta]],'CursosBS'!E:E,'CursosBS'!A:A,"*NoExiste*") -> *NoExiste* | N12: ="https://virtual.upb.edu.co/d2l/home/"&Tabla1[[#This Row],[IDCURSO]] -> https://virtual.upb.edu.co/d2l/home/*NoExiste*
A13: =_xlfn.XLOOKUP(Tabla1[[#This Row],[CodMaestro]],UnidadesOrganizaciones!D:D,UnidadesOrganizaciones!L:L,"***") -> CVFC | B13: Emprendimiento Nivel Básico | C13: 51287 | D13: 202650 | E13: =_xlfn.TEXTBEFORE(H13,"MaestroP") -> ADEM-3173- | F13: =_xlfn.XLOOKUP(Tabla1[[#This Row],[CodMaestro]],UnidadesOrganizaciones!D:D,UnidadesOrganizaciones!C:C,"***") -> Emprendimiento Nivel Básico -QMMaestroP(R) | G13: =LEFT(F13,FIND(" -",F13&" -")-1) -> Emprendimiento Nivel Básico | H13: ADEM-3173-MaestroP | I13: =Tabla1[[#This Row],[Nombre Curso]]&" - "&Tabla1[[#This Row],[Semestre]]&"-"&Tabla1[[#This Row],[NRC]] -> Emprendimiento Nivel Básico - 202650-51287 | J13: =E13&D13&"-"&C13 -> ADEM-3173-202650-51287 | K13: =_xlfn.XLOOKUP(Tabla1[[#This Row],[CodMaestro]],UnidadesOrganizaciones!D:D,UnidadesOrganizaciones!Q:Q,"***") -> 38966 | L13: =_xlfn.XLOOKUP(TEXT(Tabla1[[#This Row],[Semestre]],"######"),'CursosBS'!E:E,'CursosBS'!A:A,"***") -> 77362 | M13: =_xlfn.XLOOKUP(Tabla1[[#This Row],[CodCursoOferta]],'CursosBS'!E:E,'CursosBS'!A:A,"*NoExiste*") -> *NoExiste* | N13: ="https://virtual.upb.edu.co/d2l/home/"&Tabla1[[#This Row],[IDCURSO]] -> https://virtual.upb.edu.co/d2l/home/*NoExiste*
... A15: =_xlfn.XLOOKUP(Tabla1[[#This Row],[CodMaestro]],UnidadesOrganizaciones!D:D,UnidadesOrganizaciones!L:L,"***") -> CVFC | B15: Emprendimiento Nivel Básico | C15: 51289 | D15: 202650 | E15: =_xlfn.TEXTBEFORE(H15,"MaestroP") -> ADEM-3173- | F15: =_xlfn.XLOOKUP(Tabla1[[#This Row],[CodMaestro]],UnidadesOrganizaciones!D:D,UnidadesOrganizaciones!C:C,"***") -> Emprendimiento Nivel Básico -QMMaestroP(R) | G15: =LEFT(F15,FIND(" -",F15&" -")-1) -> Emprendimiento Nivel Básico | H15: ADEM-3173-MaestroP | I15: =Tabla1[[#This Row],[Nombre Curso]]&" - "&Tabla1[[#This Row],[Semestre]]&"-"&Tabla1[[#This Row],[NRC]] -> Emprendimiento Nivel Básico - 202650-51289 | J15: =E15&D15&"-"&C15 -> ADEM-3173-202650-51289 | K15: =_xlfn.XLOOKUP(Tabla1[[#This Row],[CodMaestro]],UnidadesOrganizaciones!D:D,UnidadesOrganizaciones!Q:Q,"***") -> 38966 | L15: =_xlfn.XLOOKUP(TEXT(Tabla1[[#This Row],[Semestre]],"######"),'CursosBS'!E:E,'CursosBS'!A:A,"***") -> 77362 | M15: =_xlfn.XLOOKUP(Tabla1[[#This Row],[CodCursoOferta]],'CursosBS'!E:E,'CursosBS'!A:A,"*NoExiste*") -> *NoExiste* | N15: ="https://virtual.upb.edu.co/d2l/home/"&Tabla1[[#This Row],[IDCURSO]] -> https://virtual.upb.edu.co/d2l/home/*NoExiste*

Sheet UnidadesOrganizaciones
A1: CourseOfferingId | B1: CourseOfferingType | C1: CourseOfferingName | D1: CourseOfferingCode | E1: OrganizationId | F1: OrganizationTypeId | G1: OrganizationType | H1: OrganizationName | I1: NivelId | J1: NivelType | K1: NivelName | L1: NivelCode | M1: ProgramaDepartamentoId | N1: ProgramaDepartamentoType | O1: ProgramaDepartamentoName | P1: ProgramaDepartamentoCode | Q1: TemplateId | R1: TemplateType | S1: TemplateName | T1: TemplateCode | U1: SemesterCode
A2: 6610 | B2: Course Offering | C2: Brightspace Training Shell | D2: TEMP_co-training-course-d2l_201810_ | E2: 6606 | F2: 1 | G2: Organization | H2: UPBVirtual | I2: 29013 | J2: Nivel | K2: Campus Virtual Extensión | L2: CVFC | M2: 34493 | N2: Programa - Departamento | O2: CVFC- UPB Virtual | P2: CVFC-UPBV | Q2: 6608 | R2: Course Template | S2: Training courses container | T2: TEMP_ct_training_d2l
A3: 6615 | B3: Course Offering | C3: Brightspace Bulk Create | D3: TEMP_utils-BCC-d2l_201810_ | E3: 6606 | F3: 1 | G3: Organization | H3: UPBVirtual | I3: 29013 | J3: Nivel | K3: Campus Virtual Extensión | L3: CVFC | M3: 34493 | N3: Programa - Departamento | O3: CVFC- UPB Virtual | P3: CVFC-UPBV | Q3: 6614 | R3: Course Template | S3: Bulk tools container | T3: Temp_ct_bulktools_d2l
A4: 6616 | B4: Course Offering | C4: Brightspace Bulk Export | D4: TEMP_utils-BCE-D2L_201810_ | E4: 6606 | F4: 1 | G4: Organization | H4: UPBVirtual | I4: 29013 | J4: Nivel | K4: Campus Virtual Extensión | L4: CVFC | M4: 34493 | N4: Programa - Departamento | O4: CVFC- UPB Virtual | P4: CVFC-UPBV | Q4: 6614 | R4: Course Template | S4: Bulk tools container | T4: Temp_ct_bulktools_d2l
A5: 6626 | B5: Course Offering | C5: Sandbox - Demo.Instructor | D5: TEMP_demo-instructor.sb_201810_ | E5: 6606 | F5: 1 | G5: Organization | H5: UPBVirtual | I5: 29013 | J5: Nivel | K5: Campus Virtual Extensión | L5: CVFC | M5: 34493 | N5: Programa - Departamento | O5: CVFC- UPB Virtual | P5: CVFC-UPBV | Q5: 6625 | R5: Course Template | S5: Brightspace Sandboxes container | T5: TEMP_ct_brightspace_sandboxes_sb
A6: 6633 | B6: Course Offering | C6: Brightspace Bulk Copy | D6: TEMP_utils-CCB-D2L_201810_ | E6: 6606 | F6: 1 | G6: Organization | H6: UPBVirtual | I6: 29013 | J6: Nivel | K6: Campus Virtual Extensión | L6: CVFC | M6: 34493 | N6: Programa - Departamento | O6: CVFC- UPB Virtual | P6: CVFC-UPBV | Q6: 6614 | R6: Course Template | S6: Bulk tools container | T6: Temp_ct_bulktools_d2l
A7: 6634 | B7: Course Offering | C7: Brightspace Admin and Data Central | D7: TEMP_admin-central-d2l_201810_ | E7: 6606 | F7: 1 | G7: Organization | H7: UPBVirtual | I7: 29013 | J7: Nivel | K7: Campus Virtual Extensión | L7: CVFC | M7: 34493 | N7: Programa - Departamento | O7: CVFC- UPB Virtual | P7: CVFC-UPBV | Q7: 6628 | R7: Course Template | S7: Implementation courses container | T7: TEMP_ct_implementation_d2l
A8: 6636 | B8: Course Offering | C8: Brightspace Implementation Center | D8: TEMP_Brightspace-101-d2l_201810_ | E8: 6606 | F8: 1 | G8: Organization | H8: UPBVirtual | I8: 29013 | J8: Nivel | K8: Campus Virtual Extensión | L8: CVFC | M8: 34493 | N8: Programa - Departamento | O8: CVFC- UPB Virtual | P8: CVFC-UPBV | Q8: 6628 | R8: Course Template | S8: Implementation courses container | T8: TEMP_ct_implementation_d2l
A9: 6642 | B9: Course Offering | C9: Brightspace Sample - Activity Feed | D9: TEMP_activityfeed-d2l-sb_201810_ | E9: 6606 | F9: 1 | G9: Organization | H9: UPBVirtual | I9: 29013 | J9: Nivel | K9: Campus Virtual Extensión | L9: CVFC | M9: 34493 | N9: Programa - Departamento | O9: CVFC- UPB Virtual | P9: CVFC-UPBV | Q9: 6625 | R9: Course Template | S9: Brightspace Sandboxes container | T9: TEMP_ct_brightspace_sandboxes_sb
A10: 6643 | B10: Course Offering | C10: Brightspace Sample - Image Based Nav | D10: TEMP_imagebasednav-d2l-sb_201810_ | E10: 6606 | F10: 1 | G10: Organization | H10: UPBVirtual | I10: 29013 | J10: Nivel | K10: Campus Virtual Extensión | L10: CVFC | M10: 34493 | N10: Programa - Departamento | O10: CVFC- UPB Virtual | P10: CVFC-UPBV | Q10: 6625 | R10: Course Template | S10: Brightspace Sandboxes container | T10: TEMP_ct_brightspace_sandboxes_sb
A11: 6645 | B11: Course Offering | C11: Brightspace Sample - Lessons | D11: TEMP_Lessons-d2l-sb_201810_ | E11: 6606 | F11: 1 | G11: Organization | H11: UPBVirtual | I11: 29013 | J11: Nivel | K11: Campus Virtual Extensión | L11: CVFC | M11: 34493 | N11: Programa - Departamento | O11: CVFC- UPB Virtual | P11: CVFC-UPBV | Q11: 6644 | R11: Course Template | S11: Brightspace Lessons Sandbox Container | T11: TEMP_lessons_sb_ct
A12: 6658 | B12: Course Offering | C12: e-moderación 50815_201850 | D12: VROb_eModeracion_201850_50815 | E12: 6606 | F12: 1 | G12: Organization | H12: UPBVirtual | I12: 29013 | J12: Nivel | K12: Campus Virtual Extensión | L12: CVFC | M12: 34493 | N12: Programa - Departamento | O12: CVFC- UPB Virtual | P12: CVFC-UPBV | Q12: 34494 | R12: Course Template | S12: Diplomado en Educación Virtual | T12: CVFC-MXEO | U12: 201850
A13: 6663 | B13: Course Offering | C13: English | D13: TEMP_BLENDED_2018_ | E13: 6606 | F13: 1 | G13: Organization | H13: UPBVirtual | I13: 29013 | J13: Nivel | K13: Campus Virtual Extensión | L13: CVFC | M13: 34493 | N13: Programa - Departamento | O13: CVFC- UPB Virtual | P13: CVFC-UPBV | Q13: 6659 | R13: Course Template | S13: Blended Course Template | T13: temp_blend
A14: 6665 | B14: Course Offering | C14: Introduction to CBE | D14: TEMP_ONLINE_2018_ | E14: 6606 | F14: 1 | G14: Organization | H14: UPBVirtual | I14: 29013 | J14: Nivel | K14: Campus Virtual Extensión | L14: CVFC | M14: 34493 | N14: Programa - Departamento | O14: CVFC- UPB Virtual | P14: CVFC-UPBV | Q14: 6664 | R14: Course Template | S14: Online Course Template | T14: temp_online
A15: 6680 | B15: Course Offering | C15: Biología humana | D15: TEMP_biologiahumana_2018_ | E15: 6606 | F15: 1 | G15: Organization | H15: UPBVirtual | I15: 29013 | J15: Nivel | K15: Campus Virtual Extensión | L15: CVFC | M15: 34493 | N15: Programa - Departamento | O15: CVFC- UPB Virtual | P15: CVFC-UPBV | Q15: 6679 | R15: Course Template | S15: Template Biología humana | T15: template_biologiahumana
A16: 6694 | B16: Course Offering | C16: Estadista Aplicada | D16: VSOb_m6-est-apli_201810_ | E16: 6606 | F16: 1 | G16: Organization | H16: UPBVirtual | I16: 29013 | J16: Nivel | K16: Campus Virtual Extensión | L16: CVFC | M16: 34493 | N16: Programa - Departamento | O16: CVFC- UPB Virtual | P16: CVFC-UPBV | Q16: 6693 | R16: Course Template | S16: template_m6_est_apli | T16: template_m6_est_apli
A17: 6748 | B17: Course Offering | C17: e-Moderación 50816_201850 | D17: VROb_eModeracion_201850_50816 | E17: 6606 | F17: 1 | G17: Organization | H17: UPBVirtual | I17: 29013 | J17: Nivel | K17: Campus Virtual Extensión | L17: CVFC | M17: 34493 | N17: Programa - Departamento | O17: CVFC- UPB Virtual | P17: CVFC-UPBV | Q17: 34494 | R17: Course Template | S17: Diplomado en Educación Virtual | T17: CVFC-MXEO | U17: 201850
A18: 6792 | B18: Course Offering | C18: Curso Modelo 1 | D18: TEMP_Curso Modelo 1_2018_ | E18: 6606 | F18: 1 | G18: Organization | H18: UPBVirtual | I18: 29013 | J18: Nivel | K18: Campus Virtual Extensión | L18: CVFC | M18: 34493 | N18: Programa - Departamento | O18: CVFC- UPB Virtual | P18: CVFC-UPBV | Q18: 6791 | R18: Course Template | S18: Curso Modelo 1 | T18: Curso Modelo 1
A19: 6794 | B19: Course Offering | C19: Curso Modelo 2 | D19: TEMP_Curso Modelo 2_2018_ | E19: 6606 | F19: 1 | G19: Organization | H19: UPBVirtual | I19: 29013 | J19: Nivel | K19: Campus Virtual Extensión | L19: CVFC | M19: 34493 | N19: Programa - Departamento | O19: CVFC- UPB Virtual | P19: CVFC-UPBV | Q19: 6793 | R19: Course Template | S19: Curso modelo 2 | T19: Curso modelo 2
A20: 6796 | B20: Course Offering | C20: Curso Modelo 3 | D20: TEMP_CursoModelo3_2018_ | E20: 6606 | F20: 1 | G20: Organization | H20: UPBVirtual | I20: 29013 | J20: Nivel | K20: Campus Virtual Extensión | L20: CVFC | M20: 34493 | N20: Programa - Departamento | O20: CVFC- UPB Virtual | P20: CVFC-UPBV | Q20: 6795 | R20: Course Template | S20: Curso Modelo 3 | T20: Curso Modelo 3
A21: 6886 | B21: Course Offering | C21: Ensayos Sergio 2 con plantilla | D21: Temp_SZA-ensayo2_201810_NRC | E21: 6606 | F21: 1 | G21: Organization | H21: UPBVirtual | I21: 29013 | J21: Nivel | K21: Campus Virtual Extensión | L21: CVFC | M21: 34493 | N21: Programa - Departamento | O21: CVFC- UPB Virtual | P21: CVFC-UPBV | Q21: 6884 | R21: Course Template | S21: PLANTILLA Ensayo | T21: PLANTILLAEnsayo
A22: 6889 | B22: Course Offering | C22: EcologiaDigital | D22: TEMP_EcologiaDigital_2018_ | E22: 6606 | F22: 1 | G22: Organization | H22: UPBVirtual | I22: 29013 | J22: Nivel | K22: Campus Virtual Extensión | L22: CVFC | M22: 34493 | N22: Programa - Departamento | O22: CVFC- UPB Virtual | P22: CVFC-UPBV | Q22: 6884 | R22: Course Template | S22: PLANTILLA Ensayo | T22: PLANTILLAEnsayo
A23: 6893 | B23: Course Offering | C23: LE + eP + LOR | D23: TEMP_co-capacitacion-d2l_201810_ | E23: 6606 | F23: 1 | G23: Organization | H23: UPBVirtual | I23: 29013 | J23: Nivel | K23: Campus Virtual Extensión | L23: CVFC | M23: 34493 | N23: Programa - Departamento | O23: CVFC- UPB Virtual | P23: CVFC-UPBV | Q23: 6892 | R23: Course Template | S23: Capacitaciones | T23: TEMP_capacita_d2l
A24: 6900 | B24: Course Offering | C24: Standardized English Test (Pregrado Med) | D24: PDOb_StandardizedEnglishTestPreMed_201950_ | E24: 6606 | F24: 1 | G24: Organization | H24: UPBVirtual | I24: 29013 | J24: Nivel | K24: Campus Virtual Extensión | L24: CVFC | M24: 35301 | N24: Programa - Departamento | O24: CVFC- Centro Lenguas-Med | P24: CVFC-MCLE | Q24: 6899 | R24: Course Template | S24: Plan_cursos_FCCentroLenguas | T24: MJLE | U24: 201950
A25: 6901 | B25: Course Offering | C25: Capacitación Administradores | D25: TEMP_CapacAdmores_2018_ | E25: 6606 | F25: 1 | G25: Organization | H25: UPBVirtual | I25: 29013 | J25: Nivel | K25: Campus Virtual Extensión | L25: CVFC | M25: 34493 | N25: Programa - Departamento | O25: CVFC- UPB Virtual | P25: CVFC-UPBV | Q25: 6608 | R25: Course Template | S25: Training courses container | T25: TEMP_ct_training_d2l
A26: 6903 | B26: Course Offering | C26: Curso_ejemplo_scorm - ADAMS | D26: TEMP_Curso-Ejemplo-Scorm_201810_ | E26: 6606 | F26: 1 | G26: Organization | H26: UPBVirtual | I26: 29013 | J26: Nivel | K26: Campus Virtual Extensión | L26: CVFC | M26: 34493 | N26: Programa - Departamento | O26: CVFC- UPB Virtual | P26: CVFC-UPBV | Q26: 6902 | R26: Course Template | S26: temp_curso_scorm | T26: temp_curso_scorm
A27: 6905 | B27: Course Offering | C27: Ejemplo con plantilla 01 | D27: TEMP_Ejemplo_201810_NRC | E27: 6606 | F27: 1 | G27: Organization | H27: UPBVirtual | I27: 29013 | J27: Nivel | K27: Campus Virtual Extensión | L27: CVFC | M27: 34493 | N27: Programa - Departamento | O27: CVFC- UPB Virtual | P27: CVFC-UPBV | Q27: 7208 | R27: Course Template | S27: Plan_ProgramaCursosEstudio | T27: Plan_ProgramaCursosEstudio
A28: 6924 | B28: Course Offering | C28: E-moderación 51244_201850 | D28: VROb_eModeracion_201850_51244 | E28: 6606 | F28: 1 | G28: Organization | H28: UPBVirtual | I28: 29013 | J28: Nivel | K28: Campus Virtual Extensión | L28: CVFC | M28: 34493 | N28: Programa - Departamento | O28: CVFC- UPB Virtual | P28: CVFC-UPBV | Q28: 34494 | R28: Course Template | S28: Diplomado en Educación Virtual | T28: CVFC-MXEO | U28: 201850
A29: 6925 | B29: Course Offering | C29: E-moderación 51243_201850 | D29: VROb_eModeracion_201850_51243 | E29: 6606 | F29: 1 | G29: Organization | H29: UPBVirtual | I29: 29013 | J29: Nivel | K29: Campus Virtual Extensión | L29: CVFC | M29: 34493 | N29: Programa - Departamento | O29: CVFC- UPB Virtual | P29: CVFC-UPBV | Q29: 34494 | R29: Course Template | S29: Diplomado en Educación Virtual | T29: CVFC-MXEO | U29: 201850
A30: 7081 | B30: Course Offering | C30: ECPD-Narrativas convergentes - **Copia20230203** | D30: VECD-5557 0048-Copia20230203 | E30: 6606 | F30: 1 | G30: Organization | H30: UPBVirtual | I30: 29010 | J30: Nivel | K30: Campus Virtual Posgrados | L30: CVFA | M30: 35347 | N30: Programa - Departamento | O30: CVFA-VPCS-Ciencias Sociales | P30: CVFA-VPCS | Q30: 6904 | R30: Course Template | S30: CVFA-VECD- Esp.Comun y Period Digital-Virt | T30: CVFA-VECD | U30: ControlVersion
A31: 7110 | B31: Course Offering | C31: ECPD - Coordinación de la especialización | D31: PDOb_ECPDCoordEspecia_2023_ | E31: 6606 | F31: 1 | G31: Organization | H31: UPBVirtual | I31: 29010 | J31: Nivel | K31: Campus Virtual Posgrados | L31: CVFA | M31: 35347 | N31: Programa - Departamento | O31: CVFA-VPCS-Ciencias Sociales | P31: CVFA-VPCS | Q31: 6904 | R31: Course Template | S31: CVFA-VECD- Esp.Comun y Period Digital-Virt | T31: CVFA-VECD | U31: CoordProgramas
A32: 7146 | B32: Course Offering | C32: Legislación de Infancia y Adolescencia_**NO USAR**-MaestroV | D32: VROb_CFCFDLegInfAdol_201841_-MaestroV | E32: 6606 | F32: 1 | G32: Organization | H32: UPBVirtual | I32: 29013 | J32: Nivel | K32: Campus Virtual Extensión | L32: CVFC | M32: 35321 | N32: Programa - Departamento | O32: CVFC- Esc. Derecho Ciencias Políticas-Med | P32: CVFC-MD | Q32: 7122 | R32: Course Template | S32: FC Ciencias Políticas-Med | T32: FC-MCPO | U32: ControlVersion
A33: 7158 | B33: Course Offering | C33: BIOLOGÍA DE LA CONSERVACIÓN - HTMaestroC | D33: 9936-2013-MaestroC | E33: 6606 | F33: 1 | G33: Organization | H33: UPBVirtual | I33: 29010 | J33: Nivel | K33: Campus Virtual Posgrados | L33: CVFA | M33: 35352 | N33: Programa - Departamento | O33: CVFA-BI-Ingeniería-Bga | P33: CVFA-BI | Q33: 7134 | R33: Course Template | S33: CVFA-VEPV- Esp. Preser y Cons R Natu-Virt | T33: CVFA-VEPV | U33: CMaestros
A34: 7163 | B34: Course Offering | C34: ECOSISTEMAS ESTRATÉGICOS Y AREAS PROTEGIDAS - HTMaestroC | D34: 9936-2015-MaestroC | E34: 6606 | F34: 1 | G34: Organization | H34: UPBVirtual | I34: 29010 | J34: Nivel | K34: Campus Virtual Posgrados | L34: CVFA | M34: 35352 | N34: Programa - Departamento | O34: CVFA-BI-Ingeniería-Bga | P34: CVFA-BI | Q34: 7134 | R34: Course Template | S34: CVFA-VEPV- Esp. Preser y Cons R Natu-Virt | T34: CVFA-VEPV | U34: CMaestros
A35: 7169 | B35: Course Offering | C35: RESTAURACIÓN Y ECOSISTEMAS -HTMaestroC | D35: CTAM-0102-MaestroC | E35: 6606 | F35: 1 | G35: Organization | H35: UPBVirtual | I35: 29010 | J35: Nivel | K35: Campus Virtual Posgrados | L35: CVFA | M35: 35352 | N35: Programa - Departamento | O35: CVFA-BI-Ingeniería-Bga | P35: CVFA-BI | Q35: 7134 | R35: Course Template | S35: CVFA-VEPV- Esp. Preser y Cons R Natu-Virt | T35: CVFA-VEPV | U35: CMaestros
A36: 7181 | B36: Course Offering | C36: GESTIÓN DE CALIDAD Y ADQUISICIONES - HTMaestroC | D36: 8821-2013-MaestroC | E36: 6606 | F36: 1 | G36: Organization | H36: UPBVirtual | I36: 29010 | J36: Nivel | K36: Campus Virtual Posgrados | L36: CVFA | M36: 35352 | N36: Programa - Departamento | O36: CVFA-BI-Ingeniería-Bga | P36: CVFA-BI | Q36: 6691 | R36: Course Template | S36: CVFA-VEGP- Esp. Gestión de Proyectos-Virt | T36: CVFA-VEGP | U36: CMaestros
A37: 7182 | B37: Course Offering | C37: ECONOMÍA AMBIENTAL -MaestroV | D37: 9936-2011-MaestroV | E37: 6606 | F37: 1 | G37: Organization | H37: UPBVirtual | I37: 29010 | J37: Nivel | K37: Campus Virtual Posgrados | L37: CVFA | M37: 35352 | N37: Programa - Departamento | O37: CVFA-BI-Ingeniería-Bga | P37: CVFA-BI | Q37: 7134 | R37: Course Template | S37: CVFA-VEPV- Esp. Preser y Cons R Natu-Virt | T37: CVFA-VEPV | U37: ControlVersion
A38: 7183 | B38: Course Offering | C38: EPRECORENA-Normatividad Ambienta- HTMaestroV | D38: VEPV-CJDL-0075-MaestroV | E38: 6606 | F38: 1 | G38: Organization | H38: UPBVirtual | I38: 29010 | J38: Nivel | K38: Campus Virtual Posgrados | L38: CVFA | M38: 35352 | N38: Programa - Departamento | O38: CVFA-BI-Ingeniería-Bga | P38: CVFA-BI | Q38: 7134 | R38: Course Template | S38: CVFA-VEPV- Esp. Preser y Cons R Natu-Virt | T38: CVFA-VEPV | U38: ControlVersion
A39: 7185 | B39: Course Offering | C39: FORMULACIÓN Y EVALUACIÓN DE PROYECTOS AMBIENTALES - HTMaestroC | D39: 9936-2014-MaestroC | E39: 6606 | F39: 1 | G39: Organization | H39: UPBVirtual | I39: 29010 | J39: Nivel | K39: Campus Virtual Posgrados | L39: CVFA | M39: 35352 | N39: Programa - Departamento | O39: CVFA-BI-Ingeniería-Bga | P39: CVFA-BI | Q39: 7134 | R39: Course Template | S39: CVFA-VEPV- Esp. Preser y Cons R Natu-Virt | T39: CVFA-VEPV | U39: CMaestros
... A41: 7194 | B41: Course Offering | C41: GESTIÓN ESTRATÉGICA -MaestroC | D41: CEOE-0321-MaestroC | E41: 6606 | F41: 1 | G41: Organization | H41: UPBVirtual | I41: 29010 | J41: Nivel | K41: Campus Virtual Posgrados | L41: CVFA | M41: 35352 | N41: Programa - Departamento | O41: CVFA-BI-Ingeniería-Bga | P41: CVFA-BI | Q41: 6691 | R41: Course Template | S41: CVFA-VEGP- Esp. Gestión de Proyectos-Virt | T41: CVFA-VEGP | U41: CMaestros
...

Sheet CursosBS
A1: ﻿OrgUnitId | B1: Organization | C1: Type | D1: Name | E1: Code | F1: StartDate | G1: EndDate | H1: IsActive | I1: CreatedDate | J1: IsDeleted | K1: DeletedDate | L1: RecycledDate | M1: Version | N1: OrgUnitTypeId | O1: PERIODO-NRC
A2: 80246 | B2: UPBVirtual | C2: Course Offering | D2: Transición en los mercados de energía - 202641-51368 | E2: 8828-2013-202641-51368 | H2: TRUE | I2: 46071.016 | J2: FALSE | M2: 442114873346 | N2: 3 | O2: =(RIGHT(CursosBS_2[[#This Row],[Code]],12)) -> 202641-51368
A3: 80245 | B3: UPBVirtual | C3: Course Offering | D3: SEMINARIO DE INVESTIGACIÓN II - 202641-51135 | E3: 3313-2053-202641-51135 | H3: TRUE | I3: 46071.016 | J3: FALSE | M3: 442114872903 | N3: 3 | O3: =(RIGHT(CursosBS_2[[#This Row],[Code]],12)) -> 202641-51135
A4: 80244 | B4: UPBVirtual | C4: Course Offering | D4: DISEÑO DE EXPERIMENTOS - 202641-51129 | E4: 9937-2002-202641-51129 | H4: TRUE | I4: 46071.015 | J4: FALSE | M4: 442114872452 | N4: 3 | O4: =(RIGHT(CursosBS_2[[#This Row],[Code]],12)) -> 202641-51129
A5: 80243 | B5: UPBVirtual | C5: Course Offering | D5: SEGURIDAD INFORMÁTICA Y EVALUACIÓN DE RIESGOS DE TI - 202641-51428 | E5: 8827-2009-202641-51428 | H5: TRUE | I5: 46071.014 | J5: FALSE | M5: 442114872084 | N5: 3 | O5: =(RIGHT(CursosBS_2[[#This Row],[Code]],12)) -> 202641-51428
A6: 80236 | B6: UPBVirtual | C6: Course Offering | D6: GERENCIA CONTEMPORÁNEA - 202641-52251 | E6: 6069-2060-202641-52251 | H6: TRUE | I6: 46071.013 | J6: FALSE | M6: 442114871685 | N6: 3 | O6: =(RIGHT(CursosBS_2[[#This Row],[Code]],12)) -> 202641-52251
A7: 80228 | B7: UPBVirtual | C7: Course Offering | D7: ENTORNO ECONÓMICO - 202641-52199 | E7: 6611-2020V-202641-52199 | H7: TRUE | I7: 46071.012 | J7: FALSE | M7: 442114871164 | N7: 3 | O7: =(RIGHT(CursosBS_2[[#This Row],[Code]],12)) -> 202641-52199
A8: 80227 | B8: UPBVirtual | C8: Course Offering | D8: Empresa e impuestos - 202641-51671 | E8: 5559-2057V-202641-51671 | H8: TRUE | I8: 46071.011 | J8: FALSE | M8: 442114870600 | N8: 3 | O8: =(RIGHT(CursosBS_2[[#This Row],[Code]],12)) -> 202641-51671
A9: 80216 | B9: UPBVirtual | C9: Course Offering | D9: Oralidad procesal - 202641-51686 | E9: 5559-2090V-202641-51686 | H9: TRUE | I9: 46071.01 | J9: FALSE | M9: 442114870205 | N9: 3 | O9: =(RIGHT(CursosBS_2[[#This Row],[Code]],12)) -> 202641-51686
A10: 80215 | B10: UPBVirtual | C10: Course Offering | D10: LENGUAJE VISUAL - QMMaestroP(T) | E10: 2027-5009V-MaestroP | H10: TRUE | I10: 46070.819 | J10: FALSE | M10: 442114842881 | N10: 3 | O10: =(RIGHT(CursosBS_2[[#This Row],[Code]],12)) -> 09V-MaestroP
A11: 80214 | B11: UPBVirtual | C11: Course Offering | D11: Seminario de Formación Investigativa II - QMMaestroP(T) | E11: 3313-2129-MaestroP | H11: TRUE | I11: 46070.816 | J11: FALSE | M11: 442114841973 | N11: 3 | O11: =(RIGHT(CursosBS_2[[#This Row],[Code]],12)) -> 129-MaestroP
A12: 80203 | B12: UPBVirtual | C12: Course Offering | D12: Economía para los negocios - 202641-52212 | E12: 6611-2035V-202641-52212 | H12: TRUE | I12: 46070.654 | J12: FALSE | M12: 442114826079 | N12: 3 | O12: =(RIGHT(CursosBS_2[[#This Row],[Code]],12)) -> 202641-52212
A13: 80168 | B13: UPBVirtual | C13: Course Offering | D13: Bienestar e incentivos - 202641-52001 | E13: 5566-2048V-202641-52001 | H13: TRUE | I13: 46070.535 | J13: FALSE | M13: 442114814059 | N13: 3 | O13: =(RIGHT(CursosBS_2[[#This Row],[Code]],12)) -> 202641-52001
... A34: 80003 | B34: UPBVirtual | C34: Course Offering | D34: Ética, Ciencia y Cultura - 202641-58288 | E34: 5568-0079-202641-58288 | H34: TRUE | I34: 46066.799 | J34: FALSE | M34: 442114480561 | N34: 3 | O34: =(RIGHT(CursosBS_2[[#This Row],[Code]],12)) -> 202641-58288
A35: 80002 | B35: UPBVirtual | C35: Course Offering | D35: Técnicas y Herramientas prospectivas 1 | E35: 6069-2002-202641V2-57808 | F35: 46083 | G35: 46107.999 | H35: TRUE | I35: 46066.737 | J35: FALSE | M35: 442114475961 | N35: 3 | O35: =(RIGHT(CursosBS_2[[#This Row],[Code]],12)) -> 2641V2-57808
A36: 80001 | B36: UPBVirtual | C36: Course Offering | D36: Indicadores de gestión | E36: 6069-2008V-202641V2-57809 | F36: 46083 | G36: 46107.999 | H36: TRUE | I36: 46066.736 | J36: FALSE | M36: 442114475934 | N36: 3 | O36: =(RIGHT(CursosBS_2[[#This Row],[Code]],12)) -> 2641V2-57809
A37: 80000 | B37: UPBVirtual | C37: Course Offering | D37: Técnicas y Herramientas prospectivas 2 | E37: 6069-2003-202641V2-50030 | F37: 46083 | G37: 46107.999 | H37: TRUE | I37: 46066.734 | J37: FALSE | M37: 442114475889 | N37: 3 | O37: =(RIGHT(CursosBS_2[[#This Row],[Code]],12)) -> 2641V2-50030
A38: 79999 | B38: UPBVirtual | C38: Course Offering | D38: Seminario de investigación II | E38: 6069-2154-202641V2-57807 | F38: 46083 | G38: 46107.999 | H38: TRUE | I38: 46066.733 | J38: FALSE | M38: 442114475845 | N38: 3 | O38: =(RIGHT(CursosBS_2[[#This Row],[Code]],12)) -> 2641V2-57807
A39: 79998 | B39: UPBVirtual | C39: Course Offering | D39: Mega tendencias y Escenarios Mundiales | E39: 6069-0174-202641V2-50033 | F39: 46083 | G39: 46107.999 | H39: TRUE | I39: 46066.732 | J39: FALSE | M39: 442114475779 | N39: 3 | O39: =(RIGHT(CursosBS_2[[#This Row],[Code]],12)) -> 2641V2-50033
A40: 79997 | B40: UPBVirtual | C40: Course Offering | D40: Prospectiva estratégica | E40: 6069-0154-202641V2-50032 | F40: 46083 | G40: 46107.999 | H40: TRUE | I40: 46066.732 | J40: FALSE | M40: 442114475712 | N40: 3 | O40: =(RIGHT(CursosBS_2[[#This Row],[Code]],12)) -> 2641V2-50032
A41: 79996 | B41: UPBVirtual | C41: Course Offering | D41: Fundamentación psicopedagógica | E41: 3313-0046-202641V2-58603 | F41: 46083 | G41: 46107.999 | H41: TRUE | I41: 46066.728 | J41: FALSE | M41: 442114475492 | N41: 3 | O41: =(RIGHT(CursosBS_2[[#This Row],[Code]],12)) -> 2641V2-58603
A42: 79995 | B42: UPBVirtual | C42: Course Offering | D42: Fundamentación pedagógica | E42: 3313-0047-202641V2-58604 | F42: 46083 | G42: 46107.999 | H42: TRUE | I42: 46066.727 | J42: FALSE | M42: 442114475433 | N42: 3 | O42: =(RIGHT(CursosBS_2[[#This Row],[Code]],12)) -> 2641V2-58604
A43: 79994 | B43: UPBVirtual | C43: Course Offering | D43: Seminario de investigación I | E43: 3313-0051-202641V2-58605 | F43: 46083 | G43: 46107.999 | H43: TRUE | I43: 46066.726 | J43: FALSE | M43: 442114475363 | N43: 3 | O43: =(RIGHT(CursosBS_2[[#This Row],[Code]],12)) -> 2641V2-58605
A44: 79993 | B44: UPBVirtual | C44: Course Offering | D44: Educación inclusiva y psicopedagogía | E44: 3313-0050-202641V2-57843 | F44: 46083 | G44: 46107.999 | H44: TRUE | I44: 46066.725 | J44: FALSE | M44: 442114475322 | N44: 3 | O44: =(RIGHT(CursosBS_2[[#This Row],[Code]],12)) -> 2641V2-57843
A45: 79992 | B45: UPBVirtual | C45: Course Offering | D45: Ética, ciencia y cultura | E45: 5568-0079-202641V2-57844 | F45: 46083 | G45: 46107.999 | H45: TRUE | I45: 46066.724 | J45: FALSE | M45: 442114475275 | N45: 3 | O45: =(RIGHT(CursosBS_2[[#This Row],[Code]],12)) -> 2641V2-57844
A46: 79991 | B46: UPBVirtual | C46: Course Offering | D46: Psicopedagogía y contextos sociales | E46: 3313-0048-202641V2-57816 | F46: 46083 | G46: 46107.999 | H46: TRUE | I46: 46066.724 | J46: FALSE | M46: 442114475228 | N46: 3 | O46: =(RIGHT(CursosBS_2[[#This Row],[Code]],12)) -> 2641V2-57816
... A54: 79983 | B54: UPBVirtual | C54: Course Offering | D54: Ejercicio De Investigación I | E54: 3313-2010-202641V2-58075 | F54: 46083 | G54: 46107.999 | H54: TRUE | I54: 46066.714 | J54: FALSE | M54: 442114474498 | N54: 3 | O54: =(RIGHT(CursosBS_2[[#This Row],[Code]],12)) -> 2641V2-58075
A55: 79982 | B55: UPBVirtual | C55: Course Offering | D55: Teoría y crítica del proyecto de diseño - 202641-51744 | E55: 2027-2023V-202641-51744 | H55: TRUE | I55: 46066.713 | J55: FALSE | M55: 442114474517 | N55: 3 | O55: =(RIGHT(CursosBS_2[[#This Row],[Code]],12)) -> 202641-51744
A56: 79981 | B56: UPBVirtual | C56: Course Offering | D56: Seminario de Investigación I: Articulo-Estudio de caso | E56: 6069-2153-202641V2-58607 | F56: 46083 | G56: 46107.999 | H56: TRUE | I56: 46066.713 | J56: FALSE | M56: 442114474193 | N56: 3 | O56: =(RIGHT(CursosBS_2[[#This Row],[Code]],12)) -> 2641V2-58607
A57: 79980 | B57: UPBVirtual | C57: Course Offering | D57: Planeación y Formulación de Proyectos | E57: 6069-2156-202641V2-58606 | F57: 46083 | G57: 46107.999 | H57: TRUE | I57: 46066.71 | J57: FALSE | M57: 442114473986 | N57: 3 | O57: =(RIGHT(CursosBS_2[[#This Row],[Code]],12)) -> 2641V2-58606
A58: 79979 | B58: UPBVirtual | C58: Course Offering | D58: Gestión del Cronograma, Costos y Riesgos | E58: 6069-2157-202641V2-58925 | F58: 46083 | G58: 46107.999 | H58: TRUE | I58: 46066.71 | J58: FALSE | M58: 442114473918 | N58: 3 | O58: =(RIGHT(CursosBS_2[[#This Row],[Code]],12)) -> 2641V2-58925
A59: 79978 | B59: UPBVirtual | C59: Course Offering | D59: Gestión del Cronograma, Costos y Riesgos | E59: 6069-2157-202641V2-57804 | F59: 46083 | G59: 46107.999 | H59: TRUE | I59: 46066.709 | J59: FALSE | M59: 442114473808 | N59: 3 | O59: =(RIGHT(CursosBS_2[[#This Row],[Code]],12)) -> 2641V2-57804
A60: 79977 | B60: UPBVirtual | C60: Course Offering | D60: Seminario de Investigación II: Articulo-Estudio de cas | E60: 6069-2154-202641V2-57803 | F60: 46083 | G60: 46107.999 | H60: TRUE | I60: 46066.708 | J60: FALSE | M60: 442114473744 | N60: 3 | O60: =(RIGHT(CursosBS_2[[#This Row],[Code]],12)) -> 2641V2-57803
A61: 79976 | B61: UPBVirtual | C61: Course Offering | D61: Evaluación y Gestión Financiera de Proyectos | E61: 6611-0036-202641V2-57888 | F61: 46083 | G61: 46107.999 | H61: TRUE | I61: 46066.707 | J61: FALSE | M61: 442114473640 | N61: 3 | O61: =(RIGHT(CursosBS_2[[#This Row],[Code]],12)) -> 2641V2-57888
A62: 79975 | B62: UPBVirtual | C62: Course Offering | D62: Estudios de Viabilidad de Proyectos | E62: 6611-0035-202641V2-57873 | F62: 46083 | G62: 46107.999 | H62: TRUE | I62: 46066.706 | J62: FALSE | M62: 442114473575 | N62: 3 | O62: =(RIGHT(CursosBS_2[[#This Row],[Code]],12)) -> 2641V2-57873
A63: 79974 | B63: UPBVirtual | C63: Course Offering | D63: Gestión Estratégica | E63: 6069-2158-202641V2-57877 | F63: 46083 | G63: 46107.999 | H63: TRUE | I63: 46066.676 | J63: FALSE | M63: 442114470973 | N63: 3 | O63: =(RIGHT(CursosBS_2[[#This Row],[Code]],12)) -> 2641V2-57877
A64: 79973 | B64: UPBVirtual | C64: Course Offering | D64: Seminario de Investigación II: Articulo-Estudio de cas | E64: 6069-2154-202641V2-57878 | F64: 46083 | G64: 46107.999 | H64: TRUE | I64: 46066.674 | J64: FALSE | M64: 442114470776 | N64: 3 | O64: =(RIGHT(CursosBS_2[[#This Row],[Code]],12)) -> 2641V2-57878
A65: 79972 | B65: UPBVirtual | C65: Course Offering | D65: Gestión Ágil de Proyectos | E65: 6069-2160-202641V2-57875 | F65: 46083 | G65: 46107.999 | H65: TRUE | I65: 46066.673 | J65: FALSE | M65: 442114470596 | N65: 3 | O65: =(RIGHT(CursosBS_2[[#This Row],[Code]],12)) -> 2641V2-57875
A66: 79971 | B66: UPBVirtual | C66: Course Offering | D66: Gestión de la Calidad y Adquisiciones | E66: 6069-2159-202641V2-57876 | F66: 46083 | G66: 46107.999 | H66: TRUE | I66: 46066.665 | J66: FALSE | M66: 442114469858 | N66: 3 | O66: =(RIGHT(CursosBS_2[[#This Row],[Code]],12)) -> 2641V2-57876
A67: 79970 | B67: UPBVirtual | C67: Course Offering | D67: Electiva: Ética de las organizaciones | E67: 5568-0073-202641V2-58924 | F67: 46083 | G67: 46107.999 | H67: TRUE | I67: 46066.663 | J67: FALSE | M67: 442114469536 | N67: 3 | O67: =(RIGHT(CursosBS_2[[#This Row],[Code]],12)) -> 2641V2-58924
...

Sheet MateriaCurso
A1: 5557-2007 | B1: =A1&"-MaestroC" -> 5557-2007-MaestroC
A2: 5559-2090V | B2: =A2&"-MaestroC" -> 5559-2090V-MaestroC
A3: 5559-2057V | B3: =A3&"-MaestroC" -> 5559-2057V-MaestroC
A4: 6611-2020V | B4: =A4&"-MaestroC" -> 6611-2020V-MaestroC
A5: 6069-2060 | B5: =A5&"-MaestroC" -> 6069-2060-MaestroC
A6: 8827-2009 | B6: =A6&"-MaestroC" -> 8827-2009-MaestroC
A7: 9937-2002 | B7: =A7&"-MaestroC" -> 9937-2002-MaestroC
A8: 3313-2053 | B8: =A8&"-MaestroC" -> 3313-2053-MaestroC
A9: 8828-2013 | B9: =A9&"-MaestroC" -> 8828-2013-MaestroC
A10: 3313-2129 | B10: =A10&"-MaestroC" -> 3313-2129-MaestroC
A11: 8828-2016 | B11: =A11&"-MaestroC" -> 8828-2016-MaestroC
